<robot name="iCub">
<!--
 =================== MATERIAUX =================== 
-->
<material name="grey">
<color rgba="0.75 0.75 0.75 1"/>
</material>
<material name="red">
</material>
<material name="white">
<color rgba="1 1 1 1"/>
</material>
<material name="dark">
<color rgba="0.15 0.15 0.15 1"/>
</material>
<material name="skin">
<color rgba="0.96 0.80 0.69 1"/>
</material>
<material name="black">
<color rgba="0.05 0.05 0.05 1"/>
</material>
<!-- =================== BASE =================== -->
<link name="base_link"/>
<link name="root_link">
<visual>
<origin xyz="-0.0364 0 0.032" rpy="1.5707963 0 -1.5707963"/>
<geometry>
<mesh filename="package://humanoid_robot/meshes/root.dae" scale="0.001 0.001 0.001"/>
</geometry>
<material name="grey"/>
</visual>
</link>
<joint name="base_link_fixed_joint" type="fixed">
<parent link="root_link"/>
<child link="base_link"/>
<origin xyz="0 0 0" rpy="0 0 0"/>
</joint>
<!-- =================== TORSE =================== -->
<link name="torso_1">
<visual>
<origin xyz="0.027046 0.032 0.0364" rpy="0 0 0"/>
<geometry>
<mesh filename="package://humanoid_robot/meshes/torso_1.dae" scale="0.001 0.001 0.001"/>
</geometry>
<material name="grey"/>
</visual>
</link>
<!--
 CORRECTION: torso_pitch — décalage vertical augmenté pour séparer du bassin 
-->
<joint name="torso_pitch" type="revolute">
<origin xyz="0 0.027046 0" rpy="1.5707963 0 -1.5707963"/>
<axis xyz="1 0 0"/>
<parent link="root_link"/>
<child link="torso_1"/>
<limit effort="50000" lower="-0.349066" upper="1.221730" velocity="50000"/>
</joint>
<link name="torso_2">
<visual>
<origin xyz="0 0.1433 0.038653" rpy="0 0 0"/>
<geometry>
<mesh filename="package://humanoid_robot/meshes/torso_2.dae" scale="0.001 0.001 0.001"/>
</geometry>
<material name="grey"/>
</visual>
</link>
<joint name="torso_roll" type="revolute">
<origin xyz="0.027046 0.032 -0.057345" rpy="0 0 0"/>
<axis xyz="0 0 -1"/>
<parent link="torso_1"/>
<child link="torso_2"/>
<limit effort="50000" lower="-0.523599" upper="0.523599" velocity="50000"/>
</joint>
<link name="chest">
<visual>
<origin xyz="0 0.09280 -0.024189" rpy="0 0 0"/>
<geometry>
<mesh filename="package://humanoid_robot/meshes/chest.dae" scale="0.001 0.001 0.001"/>
</geometry>
<material name="red"/>
</visual>
</link>
<joint name="torso_yaw" type="revolute">
<origin xyz="0 0.05 0.062842" rpy="0 0 0"/>
<axis xyz="0 -1 0"/>
<parent link="torso_2"/>
<child link="chest"/>
<limit effort="50000" lower="-0.872665" upper="0.872665" velocity="50000"/>
</joint>
<!--
 =================== COU (CORRIGÉ) =================== 
-->
<!-- neck_1 : pièce basse du cou -->
<link name="neck_1">
<visual>
<origin xyz="0.014300 -0.079997 -0.029501" rpy="0 0 0"/>
<geometry>
<mesh filename="package://humanoid_robot/meshes/neck_1.dae" scale="0.001 0.001 0.001"/>
</geometry>
<material name="dark"/>
</visual>
</link>
<!--
 CORRECTION: origin Z augmenté pour que le cou soit AU-DESSUS du chest 
-->
<joint name="neck_pitch" type="revolute">
<origin xyz="-0.014300 0.172797 0.005312" rpy="0 0 0"/>
<axis xyz="-1 0 0"/>
<parent link="chest"/>
<child link="neck_1"/>
<limit effort="50000" lower="-0.698132" upper="0.383972" velocity="50000"/>
</joint>
<link name="neck_2">
<visual>
<origin xyz="0 -0.089497 -0.050301" rpy="0 0 0"/>
<geometry>
<mesh filename="package://humanoid_robot/meshes/neck_2.dae" scale="0.001 0.001 0.001"/>
</geometry>
<material name="dark"/>
</visual>
</link>
<joint name="neck_roll" type="revolute">
<origin xyz="0.014300 0.009500 0.020800" rpy="0 0 0"/>
<axis xyz="0 0 1"/>
<parent link="neck_1"/>
<child link="neck_2"/>
<limit effort="50000" lower="-0.349066" upper="0.349066" velocity="50000"/>
</joint>
<!-- =================== TÊTE =================== -->
<link name="head">
<visual>
<origin xyz="0 -0.067153 -0.029501" rpy="0 0 0"/>
<geometry>
<mesh filename="package://humanoid_robot/meshes/head.dae" scale="0.001 0.001 0.001"/>
</geometry>
<material name="white"/>
</visual>
</link>
<joint name="neck_yaw" type="revolute">
<origin xyz="0 -0.022344 -0.020800" rpy="0 0 0"/>
<axis xyz="0 1 0"/>
<parent link="neck_2"/>
<child link="head"/>
<limit effort="50000" lower="-0.872665" upper="0.872665" velocity="50000"/>
</joint>
<!-- =================== YEUX =================== -->
<link name="l_eye">
<visual>
<origin xyz="0 0 0"/>
<geometry>
<sphere radius="0.012"/>
</geometry>
<material name="black"/>
</visual>
</link>
<joint name="l_eye_joint" type="fixed">
<parent link="head"/>
<child link="l_eye"/>
<origin xyz="0.034 0.082 0.026"/>
</joint>
<link name="r_eye">
<visual>
<origin xyz="0 0 0"/>
<geometry>
<sphere radius="0.012"/>
</geometry>
<material name="black"/>
</visual>
</link>
<joint name="r_eye_joint" type="fixed">
<parent link="head"/>
<child link="r_eye"/>
<origin xyz="-0.034 0.082 0.026"/>
</joint>
<!--
 =================== ÉPAULE GAUCHE =================== 
-->
<link name="l_shoulder_1">
<visual>
<origin xyz="-0.120257 0 -0.032223" rpy="0 0 0"/>
<geometry>
<mesh filename="package://humanoid_robot/meshes/l_shoulder_1.dae" scale="0.001 0.001 0.001"/>
</geometry>
<material name="grey"/>
</visual>
</link>
<joint name="l_shoulder_pitch" type="revolute">
<origin xyz="0.120016 0.092800 0.007969" rpy="0 0 0"/>
<axis xyz="0.965926 0 0.258819"/>
<parent link="chest"/>
<child link="l_shoulder_1"/>
<limit effort="50000" lower="-1.666789" upper="0.174533" velocity="50000"/>
</joint>
<link name="l_shoulder_2">
<visual>
<origin xyz="-0.106587 0 -0.040743" rpy="0 0 0"/>
<geometry>
<mesh filename="package://humanoid_robot/meshes/l_shoulder_2.dae" scale="0.001 0.001 0.001"/>
</geometry>
<material name="grey"/>
</visual>
</link>
<joint name="l_shoulder_roll" type="revolute">
<origin xyz="-0.013671 0 0.008520" rpy="0.270597 0.252680 -1.501557"/>
<axis xyz="-0.258819 0 0.965926"/>
<parent link="l_shoulder_1"/>
<child link="l_shoulder_2"/>
<limit effort="50000" lower="0.0" upper="2.806489" velocity="50000"/>
</joint>
<link name="l_shoulder_3">
<visual>
<origin xyz="-0.131901 0 -0.035343" rpy="0 0 0"/>
<geometry>
<mesh filename="package://humanoid_robot/meshes/l_shoulder_3.dae" scale="0.001 0.001 0.001"/>
</geometry>
<material name="grey"/>
</visual>
</link>
<joint name="l_shoulder_yaw" type="revolute">
<origin xyz="0.025314 0 -0.005401" rpy="-0.252690 -0.008519 -0.067040"/>
<axis xyz="0.965926 0 0.258819"/>
<parent link="l_shoulder_2"/>
<child link="l_shoulder_3"/>
<limit effort="50000" lower="-0.645772" upper="1.396263" velocity="50000"/>
</joint>
<link name="l_upper_arm">
<visual>
<origin xyz="-0.015 0 -0.193300" rpy="0 -1.308997 -3.141593"/>
<geometry>
<mesh filename="package://humanoid_robot/meshes/l_upper_arm.dae" scale="0.001 0.001 0.001"/>
</geometry>
<material name="red"/>
</visual>
</link>
<joint name="l_arm_ft_sensor" type="fixed">
<origin xyz="0.050930 0 0.029176" rpy="0 -1.308997 3.141593"/>
<parent link="l_shoulder_3"/>
<child link="l_upper_arm"/>
</joint>
<link name="l_elbow_1">
<visual>
<origin xyz="-0.259390 0.034000 -0.085033" rpy="0 0 0"/>
<geometry>
<mesh filename="package://humanoid_robot/meshes/l_elbow_1.dae" scale="0.001 0.001 0.001"/>
</geometry>
<material name="red"/>
</visual>
</link>
<joint name="l_elbow" type="revolute">
<origin xyz="0 0.034000 0.079260" rpy="0 -1.308997 -3.141593"/>
<axis xyz="0 -1 0"/>
<parent link="l_upper_arm"/>
<child link="l_elbow_1"/>
<limit effort="50000" lower="0.261799" upper="1.850049" velocity="50000"/>
</joint>
<link name="l_forearm">
<visual>
<origin xyz="-0.296887 0 -0.079551" rpy="0 0 0"/>
<geometry>
<mesh filename="package://humanoid_robot/meshes/l_forearm.dae" scale="0.001 0.001 0.001"/>
</geometry>
<material name="red"/>
</visual>
</link>
<joint name="l_wrist_prosup" type="revolute">
<origin xyz="0.038462 0.034000 -0.005223" rpy="0 0 0"/>
<axis xyz="0.965926 0 0.258819"/>
<parent link="l_elbow_1"/>
<child link="l_forearm"/>
<limit effort="50000" lower="-1.047198" upper="1.047198" velocity="50000"/>
</joint>
<link name="l_wrist_1">
<visual>
<origin xyz="-0.400315 -0.000007 -0.105038" rpy="0 0 0"/>
<geometry>
<mesh filename="package://humanoid_robot/meshes/l_wrist_1.dae" scale="0.001 0.001 0.001"/>
</geometry>
<material name="grey"/>
</visual>
</link>
<joint name="l_wrist_pitch" type="revolute">
<origin xyz="0.103428 0.000007 0.025487" rpy="0 0 0"/>
<axis xyz="0.258819 0 -0.965926"/>
<parent link="l_forearm"/>
<child link="l_wrist_1"/>
<limit effort="50000" lower="-1.396263" upper="0.436332" velocity="50000"/>
</joint>
<link name="l_hand">
<visual>
<origin xyz="-0.399680 0.019493 -0.107405" rpy="0 0 0"/>
<geometry>
<mesh filename="package://humanoid_robot/meshes/l_hand.dae" scale="0.001 0.001 0.001"/>
</geometry>
<material name="grey"/>
</visual>
</link>
<joint name="l_wrist_yaw" type="revolute">
<origin xyz="-0.000634 -0.019500 0.002367" rpy="0 0 0"/>
<axis xyz="0 1 0"/>
<parent link="l_wrist_1"/>
<child link="l_hand"/>
<limit effort="50000" lower="-0.349066" upper="0.436332" velocity="50000"/>
</joint>
<!--
 =================== DOIGTS GAUCHE (CORRIGÉS) =================== 
-->
<!--
 Les doigts sont maintenant positionnés relativement à l_hand correctement 
-->
<!--
 La main (l_hand) est orientée avec les doigts pointant en -Z dans son repère local 
-->
<link name="l_thumb_proximal">
<visual>
<origin xyz="0 0 -0.016"/>
<geometry>
<cylinder radius="0.008" length="0.032"/>
</geometry>
<material name="skin"/>
</visual>
</link>
<!--
 CORRECTION: pouce légèrement en avant et sur le côté, incliné 
-->
<joint name="l_thumb_proximal_j" type="fixed">
<parent link="l_hand"/>
<child link="l_thumb_proximal"/>
<origin xyz="0.020 0.010 -0.042" rpy="0 0.5 0"/>
</joint>
<link name="l_thumb_distal">
<visual>
<origin xyz="0 0 -0.012"/>
<geometry>
<cylinder radius="0.007" length="0.024"/>
</geometry>
<material name="skin"/>
</visual>
</link>
<joint name="l_thumb_distal_j" type="fixed">
<parent link="l_thumb_proximal"/>
<child link="l_thumb_distal"/>
<origin xyz="0 0 -0.034"/>
</joint>
<link name="l_index_proximal">
<visual>
<origin xyz="0 0 -0.018"/>
<geometry>
<cylinder radius="0.007" length="0.036"/>
</geometry>
<material name="skin"/>
</visual>
</link>
<!--
 CORRECTION: index aligné correctement sous la main 
-->
<joint name="l_index_proximal_j" type="fixed">
<parent link="l_hand"/>
<child link="l_index_proximal"/>
<origin xyz="0.010 0.010 -0.072"/>
</joint>
<link name="l_index_distal">
<visual>
<origin xyz="0 0 -0.014"/>
<geometry>
<cylinder radius="0.006" length="0.028"/>
</geometry>
<material name="skin"/>
</visual>
</link>
<joint name="l_index_distal_j" type="fixed">
<parent link="l_index_proximal"/>
<child link="l_index_distal"/>
<origin xyz="0 0 -0.038"/>
</joint>
<link name="l_middle_proximal">
<visual>
<origin xyz="0 0 -0.019"/>
<geometry>
<cylinder radius="0.007" length="0.038"/>
</geometry>
<material name="skin"/>
</visual>
</link>
<joint name="l_middle_proximal_j" type="fixed">
<parent link="l_hand"/>
<child link="l_middle_proximal"/>
<origin xyz="0.003 0.010 -0.074"/>
</joint>
<link name="l_middle_distal">
<visual>
<origin xyz="0 0 -0.015"/>
<geometry>
<cylinder radius="0.006" length="0.030"/>
</geometry>
<material name="skin"/>
</visual>
</link>
<joint name="l_middle_distal_j" type="fixed">
<parent link="l_middle_proximal"/>
<child link="l_middle_distal"/>
<origin xyz="0 0 -0.040"/>
</joint>
<link name="l_ring_proximal">
<visual>
<origin xyz="0 0 -0.017"/>
<geometry>
<cylinder radius="0.006" length="0.034"/>
</geometry>
<material name="skin"/>
</visual>
</link>
<joint name="l_ring_proximal_j" type="fixed">
<parent link="l_hand"/>
<child link="l_ring_proximal"/>
<origin xyz="-0.004 0.010 -0.071"/>
</joint>
<link name="l_ring_distal">
<visual>
<origin xyz="0 0 -0.013"/>
<geometry>
<cylinder radius="0.005" length="0.026"/>
</geometry>
<material name="skin"/>
</visual>
</link>
<joint name="l_ring_distal_j" type="fixed">
<parent link="l_ring_proximal"/>
<child link="l_ring_distal"/>
<origin xyz="0 0 -0.036"/>
</joint>
<link name="l_pinky_proximal">
<visual>
<origin xyz="0 0 -0.013"/>
<geometry>
<cylinder radius="0.005" length="0.026"/>
</geometry>
<material name="skin"/>
</visual>
</link>
<joint name="l_pinky_proximal_j" type="fixed">
<parent link="l_hand"/>
<child link="l_pinky_proximal"/>
<origin xyz="-0.010 0.008 -0.063"/>
</joint>
<link name="l_pinky_distal">
<visual>
<origin xyz="0 0 -0.010"/>
<geometry>
<cylinder radius="0.004" length="0.020"/>
</geometry>
<material name="skin"/>
</visual>
</link>
<joint name="l_pinky_distal_j" type="fixed">
<parent link="l_pinky_proximal"/>
<child link="l_pinky_distal"/>
<origin xyz="0 0 -0.028"/>
</joint>
<!--
 =================== ÉPAULE DROITE =================== 
-->
<link name="r_shoulder_1">
<visual>
<origin xyz="0.099008 0 -0.026529" rpy="0 0 0"/>
<geometry>
<mesh filename="package://humanoid_robot/meshes/r_shoulder_1.dae" scale="0.001 0.001 0.001"/>
</geometry>
<material name="grey"/>
</visual>
</link>
<joint name="r_shoulder_pitch" type="revolute">
<origin xyz="-0.120016 0.092800 0.007969" rpy="0 -0.523599 3.141593"/>
<axis xyz="-0.965926 0 0.258819"/>
<parent link="chest"/>
<child link="r_shoulder_1"/>
<limit effort="50000" lower="-1.666789" upper="0.174533" velocity="50000"/>
</joint>
<link name="r_shoulder_2">
<visual>
<origin xyz="0.106588 0 -0.040739" rpy="0 0 0"/>
<geometry>
<mesh filename="package://humanoid_robot/meshes/r_shoulder_2.dae" scale="0.001 0.001 0.001"/>
</geometry>
<material name="grey"/>
</visual>
</link>
<joint name="r_shoulder_roll" type="revolute">
<origin xyz="-0.007580 0 0.014210" rpy="-0.270598 -0.252680 -1.501557"/>
<axis xyz="-0.258819 0 -0.965926"/>
<parent link="r_shoulder_1"/>
<child link="r_shoulder_2"/>
<limit effort="50000" lower="0.0" upper="2.806489" velocity="50000"/>
</joint>
<link name="r_shoulder_3">
<visual>
<origin xyz="0.131934 0 -0.035352" rpy="0 0 0"/>
<geometry>
<mesh filename="package://humanoid_robot/meshes/r_shoulder_3.dae" scale="0.001 0.001 0.001"/>
</geometry>
<material name="grey"/>
</visual>
</link>
<joint name="r_shoulder_yaw" type="revolute">
<origin xyz="-0.025346 0 -0.005388" rpy="-0.252690 0.008519 0.067040"/>
<axis xyz="0.965926 0 -0.258819"/>
<parent link="r_shoulder_2"/>
<child link="r_shoulder_3"/>
<limit effort="50000" lower="-0.645772" upper="1.396263" velocity="50000"/>
</joint>
<link name="r_upper_arm">
<visual>
<origin xyz="-0.015 0 -0.193300" rpy="0 1.308997 0"/>
<geometry>
<mesh filename="package://humanoid_robot/meshes/r_upper_arm.dae" scale="0.001 0.001 0.001"/>
</geometry>
<material name="red"/>
</visual>
</link>
<joint name="r_arm_ft_sensor" type="fixed">
<origin xyz="-0.050897 0 0.029167" rpy="0 -1.308997 0"/>
<parent link="r_shoulder_3"/>
<child link="r_upper_arm"/>
</joint>
<link name="r_elbow_1">
<visual>
<origin xyz="0.259390 0.022500 -0.085033" rpy="0 0 0"/>
<geometry>
<mesh filename="package://humanoid_robot/meshes/r_elbow_1.dae" scale="0.001 0.001 0.001"/>
</geometry>
<material name="red"/>
</visual>
</link>
<joint name="r_elbow" type="revolute">
<origin xyz="0 -0.022500 0.079260" rpy="0 1.308997 0"/>
<axis xyz="0 1 0"/>
<parent link="r_upper_arm"/>
<child link="r_elbow_1"/>
<limit effort="50000" lower="0.261799" upper="1.850049" velocity="50000"/>
</joint>
<link name="r_forearm">
<visual>
<origin xyz="0.296887 0 -0.079551" rpy="0 0 0"/>
<geometry>
<mesh filename="package://humanoid_robot/meshes/r_forearm.dae" scale="0.001 0.001 0.001"/>
</geometry>
<material name="red"/>
</visual>
</link>
<joint name="r_wrist_prosup" type="revolute">
<origin xyz="-0.038462 0.022500 -0.005223" rpy="0 0 0"/>
<axis xyz="0.965926 0 -0.258819"/>
<parent link="r_elbow_1"/>
<child link="r_forearm"/>
<limit effort="50000" lower="-1.047198" upper="1.047198" velocity="50000"/>
</joint>
<link name="r_wrist_1">
<visual>
<origin xyz="0.400392 -0.000007 -0.104748" rpy="0 0 0"/>
<geometry>
<mesh filename="package://humanoid_robot/meshes/r_wrist_1.dae" scale="0.001 0.001 0.001"/>
</geometry>
<material name="grey"/>
</visual>
</link>
<joint name="r_wrist_pitch" type="revolute">
<origin xyz="-0.103505 0.000007 0.025198" rpy="0 0 0"/>
<axis xyz="0.258819 0 0.965926"/>
<parent link="r_forearm"/>
<child link="r_wrist_1"/>
<limit effort="50000" lower="-1.396263" upper="0.436332" velocity="50000"/>
</joint>
<link name="r_hand">
<visual>
<origin xyz="0.399758 0.019493 -0.107115" rpy="0 0 0"/>
<geometry>
<mesh filename="package://humanoid_robot/meshes/r_hand.dae" scale="0.001 0.001 0.001"/>
</geometry>
<material name="grey"/>
</visual>
</link>
<joint name="r_wrist_yaw" type="revolute">
<origin xyz="0.000634 -0.019500 0.002367" rpy="0 0 0"/>
<axis xyz="0 -1 0"/>
<parent link="r_wrist_1"/>
<child link="r_hand"/>
<limit effort="50000" lower="-0.349066" upper="0.436332" velocity="50000"/>
</joint>
<!--
 =================== DOIGTS DROITS (CORRIGÉS - symétrie gauche) =================== 
-->
<link name="r_thumb_proximal">
<visual>
<origin xyz="0 0 -0.016"/>
<geometry>
<cylinder radius="0.008" length="0.032"/>
</geometry>
<material name="skin"/>
</visual>
</link>
<joint name="r_thumb_proximal_j" type="fixed">
<parent link="r_hand"/>
<child link="r_thumb_proximal"/>
<origin xyz="-0.020 0.010 -0.042" rpy="0 0.5 0"/>
</joint>
<link name="r_thumb_distal">
<visual>
<origin xyz="0 0 -0.012"/>
<geometry>
<cylinder radius="0.007" length="0.024"/>
</geometry>
<material name="skin"/>
</visual>
</link>
<joint name="r_thumb_distal_j" type="fixed">
<parent link="r_thumb_proximal"/>
<child link="r_thumb_distal"/>
<origin xyz="0 0 -0.034"/>
</joint>
<link name="r_index_proximal">
<visual>
<origin xyz="0 0 -0.018"/>
<geometry>
<cylinder radius="0.007" length="0.036"/>
</geometry>
<material name="skin"/>
</visual>
</link>
<joint name="r_index_proximal_j" type="fixed">
<parent link="r_hand"/>
<child link="r_index_proximal"/>
<origin xyz="-0.010 0.010 -0.072"/>
</joint>
<link name="r_index_distal">
<visual>
<origin xyz="0 0 -0.014"/>
<geometry>
<cylinder radius="0.006" length="0.028"/>
</geometry>
<material name="skin"/>
</visual>
</link>
<joint name="r_index_distal_j" type="fixed">
<parent link="r_index_proximal"/>
<child link="r_index_distal"/>
<origin xyz="0 0 -0.038"/>
</joint>
<link name="r_middle_proximal">
<visual>
<origin xyz="0 0 -0.019"/>
<geometry>
<cylinder radius="0.007" length="0.038"/>
</geometry>
<material name="skin"/>
</visual>
</link>
<joint name="r_middle_proximal_j" type="fixed">
<parent link="r_hand"/>
<child link="r_middle_proximal"/>
<origin xyz="-0.003 0.010 -0.074"/>
</joint>
<link name="r_middle_distal">
<visual>
<origin xyz="0 0 -0.015"/>
<geometry>
<cylinder radius="0.006" length="0.030"/>
</geometry>
<material name="skin"/>
</visual>
</link>
<joint name="r_middle_distal_j" type="fixed">
<parent link="r_middle_proximal"/>
<child link="r_middle_distal"/>
<origin xyz="0 0 -0.040"/>
</joint>
<link name="r_ring_proximal">
<visual>
<origin xyz="0 0 -0.017"/>
<geometry>
<cylinder radius="0.006" length="0.034"/>
</geometry>
<material name="skin"/>
</visual>
</link>
<joint name="r_ring_proximal_j" type="fixed">
<parent link="r_hand"/>
<child link="r_ring_proximal"/>
<origin xyz="0.004 0.010 -0.071"/>
</joint>
<link name="r_ring_distal">
<visual>
<origin xyz="0 0 -0.013"/>
<geometry>
<cylinder radius="0.005" length="0.026"/>
</geometry>
<material name="skin"/>
</visual>
</link>
<joint name="r_ring_distal_j" type="fixed">
<parent link="r_ring_proximal"/>
<child link="r_ring_distal"/>
<origin xyz="0 0 -0.036"/>
</joint>
<link name="r_pinky_proximal">
<visual>
<origin xyz="0 0 -0.013"/>
<geometry>
<cylinder radius="0.005" length="0.026"/>
</geometry>
<material name="skin"/>
</visual>
</link>
<joint name="r_pinky_proximal_j" type="fixed">
<parent link="r_hand"/>
<child link="r_pinky_proximal"/>
<origin xyz="0.010 0.008 -0.063"/>
</joint>
<link name="r_pinky_distal">
<visual>
<origin xyz="0 0 -0.010"/>
<geometry>
<cylinder radius="0.004" length="0.020"/>
</geometry>
<material name="skin"/>
</visual>
</link>
<joint name="r_pinky_distal_j" type="fixed">
<parent link="r_pinky_proximal"/>
<child link="r_pinky_distal"/>
<origin xyz="0 0 -0.028"/>
</joint>
<!--
 =================== HANCHE GAUCHE =================== 
-->
<link name="l_hip_1">
<visual>
<origin xyz="0.042852 -0.026000 0.151913" rpy="1.5707963 0 1.5707963"/>
<geometry>
<mesh filename="package://humanoid_robot/meshes/l_hip_1.dae" scale="0.001 0.001 0.001"/>
</geometry>
<material name="grey"/>
</visual>
</link>
<joint name="l_hip_pitch" type="revolute">
<origin xyz="0.006452 -0.026000 -0.119913" rpy="0 0 -3.141593"/>
<axis xyz="0 -1 0"/>
<parent link="root_link"/>
<child link="l_hip_1"/>
<limit effort="55.5" lower="-0.785398" upper="2.338741" velocity="5.1"/>
</joint>
<link name="l_hip_2">
<visual>
<origin xyz="0.042852 -0.070100 0.151913" rpy="1.5707963 0 1.5707963"/>
<geometry>
<mesh filename="package://humanoid_robot/meshes/l_hip_2.dae" scale="0.001 0.001 0.001"/>
</geometry>
<material name="grey"/>
</visual>
</link>
<joint name="l_hip_roll" type="revolute">
<origin xyz="0 0.044100 0" rpy="0 0 0"/>
<axis xyz="1 0 0"/>
<parent link="l_hip_1"/>
<child link="l_hip_2"/>
<limit effort="37.0" lower="-0.349066" upper="2.094395" velocity="7.64"/>
</joint>
<link name="l_hip_3">
<visual>
<origin xyz="0.043709 0.070100 -0.226213" rpy="-1.5707963 0 -1.5707963"/>
<geometry>
<mesh filename="package://humanoid_robot/meshes/l_hip_3.dae" scale="0.001 0.001 0.001"/>
</geometry>
<material name="red"/>
</visual>
</link>
<joint name="l_leg_ft_sensor" type="fixed">
<origin xyz="-0.000830 0.000075 -0.074300" rpy="3.141593 0 0"/>
<parent link="l_hip_2"/>
<child link="l_hip_3"/>
</joint>
<link name="l_upper_leg">
<visual>
<origin xyz="0.043709 -0.070100 0.240813" rpy="1.5707963 0 1.5707963"/>
<geometry>
<mesh filename="package://humanoid_robot/meshes/l_upper_leg.dae" scale="0.001 0.001 0.001"/>
</geometry>
<material name="red"/>
</visual>
</link>
<joint name="l_hip_yaw" type="revolute">
<origin xyz="0 0 0.014400" rpy="-3.141593 0 0"/>
<axis xyz="0 0 1"/>
<parent link="l_hip_3"/>
<child link="l_upper_leg"/>
<limit effort="37.0" lower="-1.396263" upper="1.396263" velocity="7.64"/>
</joint>
<link name="l_lower_leg">
<visual>
<origin xyz="0.043709 -0.070100 0.386638" rpy="1.5707963 0 1.5707963"/>
<geometry>
<mesh filename="package://humanoid_robot/meshes/l_lower_leg.dae" scale="0.001 0.001 0.001"/>
</geometry>
<material name="red"/>
</visual>
</link>
<joint name="l_knee" type="revolute">
<origin xyz="0 0 -0.145825" rpy="0 0 0"/>
<axis xyz="0 -1 0"/>
<parent link="l_upper_leg"/>
<child link="l_lower_leg"/>
<limit effort="37.0" lower="-2.164208" upper="0.069813" velocity="7.64"/>
</joint>
<link name="l_ankle_1">
<visual>
<origin xyz="0.043709 -0.070100 0.587138" rpy="1.5707963 0 1.5707963"/>
<geometry>
<mesh filename="package://humanoid_robot/meshes/l_ankle_1.dae" scale="0.001 0.001 0.001"/>
</geometry>
<material name="grey"/>
</visual>
</link>
<joint name="l_ankle_pitch" type="revolute">
<origin xyz="0 0 -0.200500" rpy="0 0 0"/>
<axis xyz="0 1 0"/>
<parent link="l_lower_leg"/>
<child link="l_ankle_1"/>
<limit effort="37.0" lower="-0.610865" upper="0.610865" velocity="7.64"/>
</joint>
<link name="l_ankle_2">
<visual>
<origin xyz="0.043682 -0.070175 0.587138" rpy="1.5707963 0 1.5707963"/>
<geometry>
<mesh filename="package://humanoid_robot/meshes/l_ankle_2.dae" scale="0.001 0.001 0.001"/>
</geometry>
<material name="grey"/>
</visual>
</link>
<joint name="l_ankle_roll" type="revolute">
<origin xyz="0 0 0" rpy="0 0 0"/>
<axis xyz="1 0 0"/>
<parent link="l_ankle_1"/>
<child link="l_ankle_2"/>
<limit effort="37.0" lower="-0.436332" upper="0.436332" velocity="7.64"/>
</joint>
<link name="l_foot">
<visual>
<origin xyz="0.047209 0.070100 -0.647438" rpy="-1.5707963 0 -1.5707963"/>
<geometry>
<mesh filename="package://humanoid_robot/meshes/l_foot.dae" scale="0.001 0.001 0.001"/>
</geometry>
<material name="red"/>
</visual>
</link>
<joint name="l_foot_ft_sensor" type="fixed">
<origin xyz="-0.003500 0 -0.060500" rpy="3.141593 0 0"/>
<parent link="l_ankle_2"/>
<child link="l_foot"/>
</joint>
<link name="l_sole"/>
<joint name="l_sole_fixed_joint" type="fixed">
<origin xyz="0.003500 0 0.004000" rpy="-3.141593 0 0"/>
<parent link="l_foot"/>
<child link="l_sole"/>
</joint>
<!--
 =================== HANCHE DROITE =================== 
-->
<link name="r_hip_1">
<visual>
<origin xyz="0.042852 0.026000 0.151913" rpy="1.5707963 0 1.5707963"/>
<geometry>
<mesh filename="package://humanoid_robot/meshes/r_hip_1.dae" scale="0.001 0.001 0.001"/>
</geometry>
<material name="grey"/>
</visual>
</link>
<joint name="r_hip_pitch" type="revolute">
<origin xyz="0.006452 0.026000 -0.119913" rpy="0 0 -3.141593"/>
<axis xyz="0 -1 0"/>
<parent link="root_link"/>
<child link="r_hip_1"/>
<limit effort="55.5" lower="-0.785398" upper="2.338741" velocity="5.1"/>
</joint>
<link name="r_hip_2">
<visual>
<origin xyz="0.042852 0.070100 0.151913" rpy="1.5707963 0 1.5707963"/>
<geometry>
<mesh filename="package://humanoid_robot/meshes/r_hip_2.dae" scale="0.001 0.001 0.001"/>
</geometry>
<material name="grey"/>
</visual>
</link>
<joint name="r_hip_roll" type="revolute">
<origin xyz="0 -0.044100 0" rpy="0 0 0"/>
<axis xyz="-1 0 0"/>
<parent link="r_hip_1"/>
<child link="r_hip_2"/>
<limit effort="37.0" lower="-0.349066" upper="2.094395" velocity="7.64"/>
</joint>
<link name="r_hip_3">
<visual>
<origin xyz="0.043709 -0.070100 -0.226213" rpy="-1.5707963 0 -1.5707963"/>
<geometry>
<mesh filename="package://humanoid_robot/meshes/r_hip_3.dae" scale="0.001 0.001 0.001"/>
</geometry>
<material name="red"/>
</visual>
</link>
<joint name="r_leg_ft_sensor" type="fixed">
<origin xyz="-0.000936 0.000014 -0.074300" rpy="3.141593 0 0"/>
<parent link="r_hip_2"/>
<child link="r_hip_3"/>
</joint>
<link name="r_upper_leg">
<visual>
<origin xyz="0.043709 0.070100 0.240813" rpy="1.5707963 0 1.5707963"/>
<geometry>
<mesh filename="package://humanoid_robot/meshes/r_upper_leg.dae" scale="0.001 0.001 0.001"/>
</geometry>
<material name="red"/>
</visual>
</link>
<joint name="r_hip_yaw" type="revolute">
<origin xyz="0 0 0.014400" rpy="-3.141593 0 0"/>
<axis xyz="0 0 -1"/>
<parent link="r_hip_3"/>
<child link="r_upper_leg"/>
<limit effort="37.0" lower="-1.396263" upper="1.396263" velocity="7.64"/>
</joint>
<link name="r_lower_leg">
<visual>
<origin xyz="0.043709 0.070100 0.386638" rpy="1.5707963 0 1.5707963"/>
<geometry>
<mesh filename="package://humanoid_robot/meshes/r_lower_leg.dae" scale="0.001 0.001 0.001"/>
</geometry>
<material name="red"/>
</visual>
</link>
<joint name="r_knee" type="revolute">
<origin xyz="0 0 -0.145825" rpy="0 0 0"/>
<axis xyz="0 -1 0"/>
<parent link="r_upper_leg"/>
<child link="r_lower_leg"/>
<limit effort="37.0" lower="-2.164208" upper="0.069813" velocity="7.64"/>
</joint>
<link name="r_ankle_1">
<visual>
<origin xyz="0.043709 0.070100 0.587138" rpy="1.5707963 0 1.5707963"/>
<geometry>
<mesh filename="package://humanoid_robot/meshes/r_ankle_1.dae" scale="0.001 0.001 0.001"/>
</geometry>
<material name="grey"/>
</visual>
</link>
<joint name="r_ankle_pitch" type="revolute">
<origin xyz="0 0 -0.200500" rpy="0 0 0"/>
<axis xyz="0 1 0"/>
<parent link="r_lower_leg"/>
<child link="r_ankle_1"/>
<limit effort="37.0" lower="-0.610865" upper="0.610865" velocity="7.64"/>
</joint>
<link name="r_ankle_2">
<visual>
</visual>
</link>
<joint name="r_ankle_roll" type="revolute">
<origin xyz="0 0 0" rpy="0 0 0"/>
<axis xyz="-1 0 0"/>
<parent link="r_ankle_1"/>
<child link="r_ankle_2"/>
<limit effort="37.0" lower="-0.436332" upper="0.436332" velocity="7.64"/>
</joint>
<link name="r_foot">
<visual>
<origin xyz="0.047209 -0.070100 -0.647438" rpy="-1.5707963 0 -1.5707963"/>
<geometry>
<mesh filename="package://humanoid_robot/meshes/r_foot.dae" scale="0.001 0.001 0.001"/>
</geometry>
<material name="red"/>
</visual>
</link>
<joint name="r_foot_ft_sensor" type="fixed">
<origin xyz="-0.003500 0 -0.060500" rpy="3.141593 0 0"/>
<parent link="r_ankle_2"/>
<child link="r_foot"/>
</joint>
<link name="r_sole"/>
<joint name="r_sole_fixed_joint" type="fixed">
<origin xyz="0.003500 0 0.004000" rpy="-3.141593 0 0"/>
<parent link="r_foot"/>
<child link="r_sole"/>
</joint>
</robot>
